[2025-04-05T17:54:07.854+0000] {local_task_job_runner.py:123} INFO - ::group::Pre task execution logs
[2025-04-05T17:54:07.909+0000] {taskinstance.py:2614} INFO - Dependencies all met for dep_context=non-requeueable deps ti=<TaskInstance: fetch_and_store_data.trigger_dbt_run scheduled__2025-04-04T00:00:00+00:00 [queued]>
[2025-04-05T17:54:07.931+0000] {taskinstance.py:2614} INFO - Dependencies all met for dep_context=requeueable deps ti=<TaskInstance: fetch_and_store_data.trigger_dbt_run scheduled__2025-04-04T00:00:00+00:00 [queued]>
[2025-04-05T17:54:07.932+0000] {taskinstance.py:2867} INFO - Starting attempt 1 of 2
[2025-04-05T17:54:08.014+0000] {taskinstance.py:2890} INFO - Executing <Task(BashOperator): trigger_dbt_run> on 2025-04-04 00:00:00+00:00
[2025-04-05T17:54:08.022+0000] {standard_task_runner.py:72} INFO - Started process 363 to run task
[2025-04-05T17:54:08.027+0000] {standard_task_runner.py:104} INFO - Running: ['airflow', 'tasks', 'run', 'fetch_and_store_data', 'trigger_dbt_run', 'scheduled__2025-04-04T00:00:00+00:00', '--job-id', '17', '--raw', '--subdir', 'DAGS_FOLDER/reverse_etl_dag.py', '--cfg-path', '/tmp/tmpk8g9bqp9']
[2025-04-05T17:54:08.030+0000] {standard_task_runner.py:105} INFO - Job 17: Subtask trigger_dbt_run
[2025-04-05T17:54:08.161+0000] {task_command.py:467} INFO - Running <TaskInstance: fetch_and_store_data.trigger_dbt_run scheduled__2025-04-04T00:00:00+00:00 [running]> on host 20f80019eeb6
[2025-04-05T17:54:08.359+0000] {taskinstance.py:3134} INFO - Exporting env vars: AIRFLOW_CTX_DAG_OWNER='airflow' AIRFLOW_CTX_DAG_ID='fetch_and_store_data' AIRFLOW_CTX_TASK_ID='trigger_dbt_run' AIRFLOW_CTX_EXECUTION_DATE='2025-04-04T00:00:00+00:00' AIRFLOW_CTX_TRY_NUMBER='1' AIRFLOW_CTX_DAG_RUN_ID='scheduled__2025-04-04T00:00:00+00:00'
[2025-04-05T17:54:08.361+0000] {taskinstance.py:732} INFO - ::endgroup::
[2025-04-05T17:54:08.383+0000] {subprocess.py:78} INFO - Tmp dir root location: /tmp
[2025-04-05T17:54:08.385+0000] {subprocess.py:88} INFO - Running command: ['/usr/bin/bash', '-c', ' cd /usr/local/airflow/dags/reverse_etl && dbt run -m survival_rate']
[2025-04-05T17:54:08.400+0000] {subprocess.py:99} INFO - Output:
[2025-04-05T17:54:12.929+0000] {subprocess.py:106} INFO - [0m17:54:12  Running with dbt=1.9.4
[2025-04-05T17:54:13.580+0000] {subprocess.py:106} INFO - [0m17:54:13  Registered adapter: postgres=1.9.0
[2025-04-05T17:54:13.769+0000] {subprocess.py:106} INFO - [0m17:54:13  Unable to do partial parsing because saved manifest not found. Starting full parse.
[2025-04-05T17:54:16.455+0000] {subprocess.py:106} INFO - [0m17:54:16  Found 1 model, 1 source, 434 macros
[2025-04-05T17:54:16.459+0000] {subprocess.py:106} INFO - [0m17:54:16
[2025-04-05T17:54:16.461+0000] {subprocess.py:106} INFO - [0m17:54:16  Concurrency: 2 threads (target='dev')
[2025-04-05T17:54:16.463+0000] {subprocess.py:106} INFO - [0m17:54:16
[2025-04-05T17:54:33.083+0000] {subprocess.py:106} INFO - [0m17:54:33  1 of 1 START sql table model aggregated.survival_rate .......................... [RUN]
[2025-04-05T17:54:36.604+0000] {subprocess.py:106} INFO - [0m17:54:36  1 of 1 ERROR creating sql table model aggregated.survival_rate ................. [[31mERROR[0m in 3.51s]
[2025-04-05T17:54:40.087+0000] {subprocess.py:106} INFO - [0m17:54:40
[2025-04-05T17:54:40.088+0000] {subprocess.py:106} INFO - [0m17:54:40  Finished running 1 table model in 0 hours 0 minutes and 23.62 seconds (23.62s).
[2025-04-05T17:54:40.201+0000] {subprocess.py:106} INFO - [0m17:54:40
[2025-04-05T17:54:40.202+0000] {subprocess.py:106} INFO - [0m17:54:40  [31mCompleted with 1 error, 0 partial successes, and 0 warnings:[0m
[2025-04-05T17:54:40.204+0000] {subprocess.py:106} INFO - [0m17:54:40
[2025-04-05T17:54:40.206+0000] {subprocess.py:106} INFO - [0m17:54:40    Database Error in model survival_rate (models/aggregated/survival_rate.sql)
[2025-04-05T17:54:40.207+0000] {subprocess.py:106} INFO -   syntax error at or near "s"
[2025-04-05T17:54:40.208+0000] {subprocess.py:106} INFO -   LINE 27: s
[2025-04-05T17:54:40.209+0000] {subprocess.py:106} INFO -            ^
[2025-04-05T17:54:40.209+0000] {subprocess.py:106} INFO -   compiled code at target/run/reverse_etl/models/aggregated/survival_rate.sql
[2025-04-05T17:54:40.210+0000] {subprocess.py:106} INFO - [0m17:54:40
[2025-04-05T17:54:40.211+0000] {subprocess.py:106} INFO - [0m17:54:40  Done. PASS=0 WARN=0 ERROR=1 SKIP=0 TOTAL=1
[2025-04-05T17:54:43.100+0000] {subprocess.py:110} INFO - Command exited with return code 1
[2025-04-05T17:54:43.136+0000] {taskinstance.py:3313} ERROR - Task failed with exception
Traceback (most recent call last):
  File "/home/airflow/.local/lib/python3.12/site-packages/airflow/models/taskinstance.py", line 768, in _execute_task
    result = _execute_callable(context=context, **execute_callable_kwargs)
             ^^^^^^^^^^^^^^^^^^^^^^^^^^^^^^^^^^^^^^^^^^^^^^^^^^^^^^^^^^^^^
  File "/home/airflow/.local/lib/python3.12/site-packages/airflow/models/taskinstance.py", line 734, in _execute_callable
    return ExecutionCallableRunner(
           ^^^^^^^^^^^^^^^^^^^^^^^^
  File "/home/airflow/.local/lib/python3.12/site-packages/airflow/utils/operator_helpers.py", line 252, in run
    return self.func(*args, **kwargs)
           ^^^^^^^^^^^^^^^^^^^^^^^^^^
  File "/home/airflow/.local/lib/python3.12/site-packages/airflow/models/baseoperator.py", line 424, in wrapper
    return func(self, *args, **kwargs)
           ^^^^^^^^^^^^^^^^^^^^^^^^^^^
  File "/home/airflow/.local/lib/python3.12/site-packages/airflow/operators/bash.py", line 276, in execute
    raise AirflowException(
airflow.exceptions.AirflowException: Bash command failed. The command returned a non-zero exit code 1.
[2025-04-05T17:54:43.169+0000] {taskinstance.py:1226} INFO - Marking task as UP_FOR_RETRY. dag_id=fetch_and_store_data, task_id=trigger_dbt_run, run_id=scheduled__2025-04-04T00:00:00+00:00, execution_date=20250404T000000, start_date=20250405T175407, end_date=20250405T175443
[2025-04-05T17:54:43.345+0000] {taskinstance.py:341} INFO - ::group::Post task execution logs
[2025-04-05T17:54:43.348+0000] {standard_task_runner.py:124} ERROR - Failed to execute job 17 for task trigger_dbt_run (Bash command failed. The command returned a non-zero exit code 1.; 363)
Traceback (most recent call last):
  File "/home/airflow/.local/lib/python3.12/site-packages/airflow/task/task_runner/standard_task_runner.py", line 117, in _start_by_fork
    ret = args.func(args, dag=self.dag)
          ^^^^^^^^^^^^^^^^^^^^^^^^^^^^^
  File "/home/airflow/.local/lib/python3.12/site-packages/airflow/cli/cli_config.py", line 49, in command
    return func(*args, **kwargs)
           ^^^^^^^^^^^^^^^^^^^^^
  File "/home/airflow/.local/lib/python3.12/site-packages/airflow/utils/cli.py", line 116, in wrapper
    return f(*args, **kwargs)
           ^^^^^^^^^^^^^^^^^^
  File "/home/airflow/.local/lib/python3.12/site-packages/airflow/cli/commands/task_command.py", line 483, in task_run
    task_return_code = _run_task_by_selected_method(args, _dag, ti)
                       ^^^^^^^^^^^^^^^^^^^^^^^^^^^^^^^^^^^^^^^^^^^^
  File "/home/airflow/.local/lib/python3.12/site-packages/airflow/cli/commands/task_command.py", line 256, in _run_task_by_selected_method
    return _run_raw_task(args, ti)
           ^^^^^^^^^^^^^^^^^^^^^^^
  File "/home/airflow/.local/lib/python3.12/site-packages/airflow/cli/commands/task_command.py", line 341, in _run_raw_task
    return ti._run_raw_task(
           ^^^^^^^^^^^^^^^^^
  File "/home/airflow/.local/lib/python3.12/site-packages/airflow/utils/session.py", line 97, in wrapper
    return func(*args, session=session, **kwargs)
           ^^^^^^^^^^^^^^^^^^^^^^^^^^^^^^^^^^^^^^
  File "/home/airflow/.local/lib/python3.12/site-packages/airflow/models/taskinstance.py", line 3006, in _run_raw_task
    return _run_raw_task(
           ^^^^^^^^^^^^^^
  File "/home/airflow/.local/lib/python3.12/site-packages/airflow/models/taskinstance.py", line 274, in _run_raw_task
    TaskInstance._execute_task_with_callbacks(
  File "/home/airflow/.local/lib/python3.12/site-packages/airflow/models/taskinstance.py", line 3161, in _execute_task_with_callbacks
    result = self._execute_task(context, task_orig)
             ^^^^^^^^^^^^^^^^^^^^^^^^^^^^^^^^^^^^^^
  File "/home/airflow/.local/lib/python3.12/site-packages/airflow/models/taskinstance.py", line 3185, in _execute_task
    return _execute_task(self, context, task_orig)
           ^^^^^^^^^^^^^^^^^^^^^^^^^^^^^^^^^^^^^^^
  File "/home/airflow/.local/lib/python3.12/site-packages/airflow/models/taskinstance.py", line 768, in _execute_task
    result = _execute_callable(context=context, **execute_callable_kwargs)
             ^^^^^^^^^^^^^^^^^^^^^^^^^^^^^^^^^^^^^^^^^^^^^^^^^^^^^^^^^^^^^
  File "/home/airflow/.local/lib/python3.12/site-packages/airflow/models/taskinstance.py", line 734, in _execute_callable
    return ExecutionCallableRunner(
           ^^^^^^^^^^^^^^^^^^^^^^^^
  File "/home/airflow/.local/lib/python3.12/site-packages/airflow/utils/operator_helpers.py", line 252, in run
    return self.func(*args, **kwargs)
           ^^^^^^^^^^^^^^^^^^^^^^^^^^
  File "/home/airflow/.local/lib/python3.12/site-packages/airflow/models/baseoperator.py", line 424, in wrapper
    return func(self, *args, **kwargs)
           ^^^^^^^^^^^^^^^^^^^^^^^^^^^
  File "/home/airflow/.local/lib/python3.12/site-packages/airflow/operators/bash.py", line 276, in execute
    raise AirflowException(
airflow.exceptions.AirflowException: Bash command failed. The command returned a non-zero exit code 1.
[2025-04-05T17:54:43.381+0000] {local_task_job_runner.py:266} INFO - Task exited with return code 1
[2025-04-05T17:54:43.476+0000] {taskinstance.py:3901} INFO - 0 downstream tasks scheduled from follow-on schedule check
[2025-04-05T17:54:43.481+0000] {local_task_job_runner.py:245} INFO - ::endgroup::
