[2025-04-05T17:59:48.111+0000] {local_task_job_runner.py:123} INFO - ::group::Pre task execution logs
[2025-04-05T17:59:48.157+0000] {taskinstance.py:2614} INFO - Dependencies all met for dep_context=non-requeueable deps ti=<TaskInstance: fetch_and_store_data.trigger_dbt_run scheduled__2025-04-04T00:00:00+00:00 [queued]>
[2025-04-05T17:59:48.181+0000] {taskinstance.py:2614} INFO - Dependencies all met for dep_context=requeueable deps ti=<TaskInstance: fetch_and_store_data.trigger_dbt_run scheduled__2025-04-04T00:00:00+00:00 [queued]>
[2025-04-05T17:59:48.182+0000] {taskinstance.py:2867} INFO - Starting attempt 2 of 2
[2025-04-05T17:59:48.242+0000] {taskinstance.py:2890} INFO - Executing <Task(BashOperator): trigger_dbt_run> on 2025-04-04 00:00:00+00:00
[2025-04-05T17:59:48.247+0000] {standard_task_runner.py:72} INFO - Started process 90 to run task
[2025-04-05T17:59:48.250+0000] {standard_task_runner.py:104} INFO - Running: ['airflow', 'tasks', 'run', 'fetch_and_store_data', 'trigger_dbt_run', 'scheduled__2025-04-04T00:00:00+00:00', '--job-id', '23', '--raw', '--subdir', 'DAGS_FOLDER/reverse_etl_dag.py', '--cfg-path', '/tmp/tmpcd5ugfci']
[2025-04-05T17:59:48.253+0000] {standard_task_runner.py:105} INFO - Job 23: Subtask trigger_dbt_run
[2025-04-05T17:59:48.384+0000] {task_command.py:467} INFO - Running <TaskInstance: fetch_and_store_data.trigger_dbt_run scheduled__2025-04-04T00:00:00+00:00 [running]> on host 830eaf47e7f8
[2025-04-05T17:59:48.543+0000] {taskinstance.py:3134} INFO - Exporting env vars: AIRFLOW_CTX_DAG_OWNER='airflow' AIRFLOW_CTX_DAG_ID='fetch_and_store_data' AIRFLOW_CTX_TASK_ID='trigger_dbt_run' AIRFLOW_CTX_EXECUTION_DATE='2025-04-04T00:00:00+00:00' AIRFLOW_CTX_TRY_NUMBER='2' AIRFLOW_CTX_DAG_RUN_ID='scheduled__2025-04-04T00:00:00+00:00'
[2025-04-05T17:59:48.544+0000] {taskinstance.py:732} INFO - ::endgroup::
[2025-04-05T17:59:48.588+0000] {subprocess.py:78} INFO - Tmp dir root location: /tmp
[2025-04-05T17:59:48.590+0000] {subprocess.py:88} INFO - Running command: ['/usr/bin/bash', '-c', ' cd /usr/local/airflow/dags/reverse_etl && dbt run -m survival_rate']
[2025-04-05T17:59:48.599+0000] {subprocess.py:99} INFO - Output:
[2025-04-05T17:59:52.320+0000] {subprocess.py:106} INFO - Usage: dbt run [OPTIONS]
[2025-04-05T17:59:52.321+0000] {subprocess.py:106} INFO - Try 'dbt run -h' for help.
[2025-04-05T17:59:52.321+0000] {subprocess.py:106} INFO - 
[2025-04-05T17:59:52.322+0000] {subprocess.py:106} INFO - Error: Invalid value for '--profiles-dir': Path '/home/airflow/.dbt' does not exist.
[2025-04-05T17:59:52.612+0000] {subprocess.py:110} INFO - Command exited with return code 2
[2025-04-05T17:59:52.630+0000] {taskinstance.py:3313} ERROR - Task failed with exception
Traceback (most recent call last):
  File "/home/airflow/.local/lib/python3.12/site-packages/airflow/models/taskinstance.py", line 768, in _execute_task
    result = _execute_callable(context=context, **execute_callable_kwargs)
             ^^^^^^^^^^^^^^^^^^^^^^^^^^^^^^^^^^^^^^^^^^^^^^^^^^^^^^^^^^^^^
  File "/home/airflow/.local/lib/python3.12/site-packages/airflow/models/taskinstance.py", line 734, in _execute_callable
    return ExecutionCallableRunner(
           ^^^^^^^^^^^^^^^^^^^^^^^^
  File "/home/airflow/.local/lib/python3.12/site-packages/airflow/utils/operator_helpers.py", line 252, in run
    return self.func(*args, **kwargs)
           ^^^^^^^^^^^^^^^^^^^^^^^^^^
  File "/home/airflow/.local/lib/python3.12/site-packages/airflow/models/baseoperator.py", line 424, in wrapper
    return func(self, *args, **kwargs)
           ^^^^^^^^^^^^^^^^^^^^^^^^^^^
  File "/home/airflow/.local/lib/python3.12/site-packages/airflow/operators/bash.py", line 276, in execute
    raise AirflowException(
airflow.exceptions.AirflowException: Bash command failed. The command returned a non-zero exit code 2.
[2025-04-05T17:59:52.637+0000] {taskinstance.py:1226} INFO - Marking task as FAILED. dag_id=fetch_and_store_data, task_id=trigger_dbt_run, run_id=scheduled__2025-04-04T00:00:00+00:00, execution_date=20250404T000000, start_date=20250405T175948, end_date=20250405T175952
[2025-04-05T17:59:52.751+0000] {taskinstance.py:341} INFO - ::group::Post task execution logs
[2025-04-05T17:59:52.752+0000] {standard_task_runner.py:124} ERROR - Failed to execute job 23 for task trigger_dbt_run (Bash command failed. The command returned a non-zero exit code 2.; 90)
Traceback (most recent call last):
  File "/home/airflow/.local/lib/python3.12/site-packages/airflow/task/task_runner/standard_task_runner.py", line 117, in _start_by_fork
    ret = args.func(args, dag=self.dag)
          ^^^^^^^^^^^^^^^^^^^^^^^^^^^^^
  File "/home/airflow/.local/lib/python3.12/site-packages/airflow/cli/cli_config.py", line 49, in command
    return func(*args, **kwargs)
           ^^^^^^^^^^^^^^^^^^^^^
  File "/home/airflow/.local/lib/python3.12/site-packages/airflow/utils/cli.py", line 116, in wrapper
    return f(*args, **kwargs)
           ^^^^^^^^^^^^^^^^^^
  File "/home/airflow/.local/lib/python3.12/site-packages/airflow/cli/commands/task_command.py", line 483, in task_run
    task_return_code = _run_task_by_selected_method(args, _dag, ti)
                       ^^^^^^^^^^^^^^^^^^^^^^^^^^^^^^^^^^^^^^^^^^^^
  File "/home/airflow/.local/lib/python3.12/site-packages/airflow/cli/commands/task_command.py", line 256, in _run_task_by_selected_method
    return _run_raw_task(args, ti)
           ^^^^^^^^^^^^^^^^^^^^^^^
  File "/home/airflow/.local/lib/python3.12/site-packages/airflow/cli/commands/task_command.py", line 341, in _run_raw_task
    return ti._run_raw_task(
           ^^^^^^^^^^^^^^^^^
  File "/home/airflow/.local/lib/python3.12/site-packages/airflow/utils/session.py", line 97, in wrapper
    return func(*args, session=session, **kwargs)
           ^^^^^^^^^^^^^^^^^^^^^^^^^^^^^^^^^^^^^^
  File "/home/airflow/.local/lib/python3.12/site-packages/airflow/models/taskinstance.py", line 3006, in _run_raw_task
    return _run_raw_task(
           ^^^^^^^^^^^^^^
  File "/home/airflow/.local/lib/python3.12/site-packages/airflow/models/taskinstance.py", line 274, in _run_raw_task
    TaskInstance._execute_task_with_callbacks(
  File "/home/airflow/.local/lib/python3.12/site-packages/airflow/models/taskinstance.py", line 3161, in _execute_task_with_callbacks
    result = self._execute_task(context, task_orig)
             ^^^^^^^^^^^^^^^^^^^^^^^^^^^^^^^^^^^^^^
  File "/home/airflow/.local/lib/python3.12/site-packages/airflow/models/taskinstance.py", line 3185, in _execute_task
    return _execute_task(self, context, task_orig)
           ^^^^^^^^^^^^^^^^^^^^^^^^^^^^^^^^^^^^^^^
  File "/home/airflow/.local/lib/python3.12/site-packages/airflow/models/taskinstance.py", line 768, in _execute_task
    result = _execute_callable(context=context, **execute_callable_kwargs)
             ^^^^^^^^^^^^^^^^^^^^^^^^^^^^^^^^^^^^^^^^^^^^^^^^^^^^^^^^^^^^^
  File "/home/airflow/.local/lib/python3.12/site-packages/airflow/models/taskinstance.py", line 734, in _execute_callable
    return ExecutionCallableRunner(
           ^^^^^^^^^^^^^^^^^^^^^^^^
  File "/home/airflow/.local/lib/python3.12/site-packages/airflow/utils/operator_helpers.py", line 252, in run
    return self.func(*args, **kwargs)
           ^^^^^^^^^^^^^^^^^^^^^^^^^^
  File "/home/airflow/.local/lib/python3.12/site-packages/airflow/models/baseoperator.py", line 424, in wrapper
    return func(self, *args, **kwargs)
           ^^^^^^^^^^^^^^^^^^^^^^^^^^^
  File "/home/airflow/.local/lib/python3.12/site-packages/airflow/operators/bash.py", line 276, in execute
    raise AirflowException(
airflow.exceptions.AirflowException: Bash command failed. The command returned a non-zero exit code 2.
[2025-04-05T17:59:52.762+0000] {local_task_job_runner.py:266} INFO - Task exited with return code 1
[2025-04-05T17:59:52.797+0000] {taskinstance.py:3901} INFO - 0 downstream tasks scheduled from follow-on schedule check
[2025-04-05T17:59:52.799+0000] {local_task_job_runner.py:245} INFO - ::endgroup::
