[2025-04-06T02:32:57.446+0000] {local_task_job_runner.py:123} INFO - ::group::Pre task execution logs
[2025-04-06T02:32:57.496+0000] {taskinstance.py:2614} INFO - Dependencies all met for dep_context=non-requeueable deps ti=<TaskInstance: fetch_and_store_data.trigger_dbt_run manual__2025-04-05T20:27:06.631851+00:00 [queued]>
[2025-04-06T02:32:57.525+0000] {taskinstance.py:2614} INFO - Dependencies all met for dep_context=requeueable deps ti=<TaskInstance: fetch_and_store_data.trigger_dbt_run manual__2025-04-05T20:27:06.631851+00:00 [queued]>
[2025-04-06T02:32:57.526+0000] {taskinstance.py:2867} INFO - Starting attempt 2 of 2
[2025-04-06T02:32:57.590+0000] {taskinstance.py:2890} INFO - Executing <Task(BashOperator): trigger_dbt_run> on 2025-04-05 20:27:06.631851+00:00
[2025-04-06T02:32:57.601+0000] {standard_task_runner.py:72} INFO - Started process 118 to run task
[2025-04-06T02:32:57.608+0000] {standard_task_runner.py:104} INFO - Running: ['airflow', 'tasks', 'run', 'fetch_and_store_data', 'trigger_dbt_run', 'manual__2025-04-05T20:27:06.631851+00:00', '--job-id', '77', '--raw', '--subdir', 'DAGS_FOLDER/reverse_etl_dag.py', '--cfg-path', '/tmp/tmp06dujteq']
[2025-04-06T02:32:57.615+0000] {standard_task_runner.py:105} INFO - Job 77: Subtask trigger_dbt_run
[2025-04-06T02:32:57.843+0000] {task_command.py:467} INFO - Running <TaskInstance: fetch_and_store_data.trigger_dbt_run manual__2025-04-05T20:27:06.631851+00:00 [running]> on host 830eaf47e7f8
[2025-04-06T02:32:58.113+0000] {taskinstance.py:3134} INFO - Exporting env vars: AIRFLOW_CTX_DAG_OWNER='airflow' AIRFLOW_CTX_DAG_ID='fetch_and_store_data' AIRFLOW_CTX_TASK_ID='trigger_dbt_run' AIRFLOW_CTX_EXECUTION_DATE='2025-04-05T20:27:06.631851+00:00' AIRFLOW_CTX_TRY_NUMBER='2' AIRFLOW_CTX_DAG_RUN_ID='manual__2025-04-05T20:27:06.631851+00:00'
[2025-04-06T02:32:58.115+0000] {taskinstance.py:732} INFO - ::endgroup::
[2025-04-06T02:32:58.149+0000] {subprocess.py:78} INFO - Tmp dir root location: /tmp
[2025-04-06T02:32:58.151+0000] {subprocess.py:88} INFO - Running command: ['/usr/bin/bash', '-c', ' cd /usr/local/airflow/dags/reverse_etl && dbt run']
[2025-04-06T02:32:58.169+0000] {subprocess.py:99} INFO - Output:
[2025-04-06T02:33:07.444+0000] {subprocess.py:106} INFO - [0m02:33:07  Running with dbt=1.9.4
[2025-04-06T02:33:08.462+0000] {subprocess.py:106} INFO - [0m02:33:08  Registered adapter: postgres=1.9.0
[2025-04-06T02:33:11.422+0000] {subprocess.py:106} INFO - [0m02:33:11  Found 1 model, 1 source, 434 macros
[2025-04-06T02:33:11.431+0000] {subprocess.py:106} INFO - [0m02:33:11
[2025-04-06T02:33:11.434+0000] {subprocess.py:106} INFO - [0m02:33:11  Concurrency: 2 threads (target='dev')
[2025-04-06T02:33:11.437+0000] {subprocess.py:106} INFO - [0m02:33:11
[2025-04-06T02:33:26.648+0000] {subprocess.py:106} INFO - [0m02:33:26  1 of 1 START sql table model aggregated.survival_rate .......................... [RUN]
[2025-04-06T02:33:30.395+0000] {subprocess.py:106} INFO - [0m02:33:30  1 of 1 ERROR creating sql table model aggregated.survival_rate ................. [[31mERROR[0m in 3.74s]
[2025-04-06T02:33:33.704+0000] {subprocess.py:106} INFO - [0m02:33:33
[2025-04-06T02:33:33.705+0000] {subprocess.py:106} INFO - [0m02:33:33  Finished running 1 table model in 0 hours 0 minutes and 22.26 seconds (22.26s).
[2025-04-06T02:33:33.801+0000] {subprocess.py:106} INFO - [0m02:33:33
[2025-04-06T02:33:33.802+0000] {subprocess.py:106} INFO - [0m02:33:33  [31mCompleted with 1 error, 0 partial successes, and 0 warnings:[0m
[2025-04-06T02:33:33.804+0000] {subprocess.py:106} INFO - [0m02:33:33
[2025-04-06T02:33:33.805+0000] {subprocess.py:106} INFO - [0m02:33:33    Database Error in model survival_rate (models/aggregated/survival_rate.sql)
[2025-04-06T02:33:33.806+0000] {subprocess.py:106} INFO -   relation "public.titanic" does not exist
[2025-04-06T02:33:33.807+0000] {subprocess.py:106} INFO -   LINE 31: from "railway"."public"."titanic"
[2025-04-06T02:33:33.808+0000] {subprocess.py:106} INFO -                 ^
[2025-04-06T02:33:33.809+0000] {subprocess.py:106} INFO -   compiled code at target/run/reverse_etl/models/aggregated/survival_rate.sql
[2025-04-06T02:33:33.810+0000] {subprocess.py:106} INFO - [0m02:33:33
[2025-04-06T02:33:33.811+0000] {subprocess.py:106} INFO - [0m02:33:33  Done. PASS=0 WARN=0 ERROR=1 SKIP=0 TOTAL=1
[2025-04-06T02:33:35.535+0000] {subprocess.py:110} INFO - Command exited with return code 1
[2025-04-06T02:33:35.561+0000] {taskinstance.py:3313} ERROR - Task failed with exception
Traceback (most recent call last):
  File "/home/airflow/.local/lib/python3.12/site-packages/airflow/models/taskinstance.py", line 768, in _execute_task
    result = _execute_callable(context=context, **execute_callable_kwargs)
             ^^^^^^^^^^^^^^^^^^^^^^^^^^^^^^^^^^^^^^^^^^^^^^^^^^^^^^^^^^^^^
  File "/home/airflow/.local/lib/python3.12/site-packages/airflow/models/taskinstance.py", line 734, in _execute_callable
    return ExecutionCallableRunner(
           ^^^^^^^^^^^^^^^^^^^^^^^^
  File "/home/airflow/.local/lib/python3.12/site-packages/airflow/utils/operator_helpers.py", line 252, in run
    return self.func(*args, **kwargs)
           ^^^^^^^^^^^^^^^^^^^^^^^^^^
  File "/home/airflow/.local/lib/python3.12/site-packages/airflow/models/baseoperator.py", line 424, in wrapper
    return func(self, *args, **kwargs)
           ^^^^^^^^^^^^^^^^^^^^^^^^^^^
  File "/home/airflow/.local/lib/python3.12/site-packages/airflow/operators/bash.py", line 276, in execute
    raise AirflowException(
airflow.exceptions.AirflowException: Bash command failed. The command returned a non-zero exit code 1.
[2025-04-06T02:33:35.571+0000] {taskinstance.py:1226} INFO - Marking task as FAILED. dag_id=fetch_and_store_data, task_id=trigger_dbt_run, run_id=manual__2025-04-05T20:27:06.631851+00:00, execution_date=20250405T202706, start_date=20250406T023257, end_date=20250406T023335
[2025-04-06T02:33:35.704+0000] {taskinstance.py:341} INFO - ::group::Post task execution logs
[2025-04-06T02:33:35.706+0000] {standard_task_runner.py:124} ERROR - Failed to execute job 77 for task trigger_dbt_run (Bash command failed. The command returned a non-zero exit code 1.; 118)
Traceback (most recent call last):
  File "/home/airflow/.local/lib/python3.12/site-packages/airflow/task/task_runner/standard_task_runner.py", line 117, in _start_by_fork
    ret = args.func(args, dag=self.dag)
          ^^^^^^^^^^^^^^^^^^^^^^^^^^^^^
  File "/home/airflow/.local/lib/python3.12/site-packages/airflow/cli/cli_config.py", line 49, in command
    return func(*args, **kwargs)
           ^^^^^^^^^^^^^^^^^^^^^
  File "/home/airflow/.local/lib/python3.12/site-packages/airflow/utils/cli.py", line 116, in wrapper
    return f(*args, **kwargs)
           ^^^^^^^^^^^^^^^^^^
  File "/home/airflow/.local/lib/python3.12/site-packages/airflow/cli/commands/task_command.py", line 483, in task_run
    task_return_code = _run_task_by_selected_method(args, _dag, ti)
                       ^^^^^^^^^^^^^^^^^^^^^^^^^^^^^^^^^^^^^^^^^^^^
  File "/home/airflow/.local/lib/python3.12/site-packages/airflow/cli/commands/task_command.py", line 256, in _run_task_by_selected_method
    return _run_raw_task(args, ti)
           ^^^^^^^^^^^^^^^^^^^^^^^
  File "/home/airflow/.local/lib/python3.12/site-packages/airflow/cli/commands/task_command.py", line 341, in _run_raw_task
    return ti._run_raw_task(
           ^^^^^^^^^^^^^^^^^
  File "/home/airflow/.local/lib/python3.12/site-packages/airflow/utils/session.py", line 97, in wrapper
    return func(*args, session=session, **kwargs)
           ^^^^^^^^^^^^^^^^^^^^^^^^^^^^^^^^^^^^^^
  File "/home/airflow/.local/lib/python3.12/site-packages/airflow/models/taskinstance.py", line 3006, in _run_raw_task
    return _run_raw_task(
           ^^^^^^^^^^^^^^
  File "/home/airflow/.local/lib/python3.12/site-packages/airflow/models/taskinstance.py", line 274, in _run_raw_task
    TaskInstance._execute_task_with_callbacks(
  File "/home/airflow/.local/lib/python3.12/site-packages/airflow/models/taskinstance.py", line 3161, in _execute_task_with_callbacks
    result = self._execute_task(context, task_orig)
             ^^^^^^^^^^^^^^^^^^^^^^^^^^^^^^^^^^^^^^
  File "/home/airflow/.local/lib/python3.12/site-packages/airflow/models/taskinstance.py", line 3185, in _execute_task
    return _execute_task(self, context, task_orig)
           ^^^^^^^^^^^^^^^^^^^^^^^^^^^^^^^^^^^^^^^
  File "/home/airflow/.local/lib/python3.12/site-packages/airflow/models/taskinstance.py", line 768, in _execute_task
    result = _execute_callable(context=context, **execute_callable_kwargs)
             ^^^^^^^^^^^^^^^^^^^^^^^^^^^^^^^^^^^^^^^^^^^^^^^^^^^^^^^^^^^^^
  File "/home/airflow/.local/lib/python3.12/site-packages/airflow/models/taskinstance.py", line 734, in _execute_callable
    return ExecutionCallableRunner(
           ^^^^^^^^^^^^^^^^^^^^^^^^
  File "/home/airflow/.local/lib/python3.12/site-packages/airflow/utils/operator_helpers.py", line 252, in run
    return self.func(*args, **kwargs)
           ^^^^^^^^^^^^^^^^^^^^^^^^^^
  File "/home/airflow/.local/lib/python3.12/site-packages/airflow/models/baseoperator.py", line 424, in wrapper
    return func(self, *args, **kwargs)
           ^^^^^^^^^^^^^^^^^^^^^^^^^^^
  File "/home/airflow/.local/lib/python3.12/site-packages/airflow/operators/bash.py", line 276, in execute
    raise AirflowException(
airflow.exceptions.AirflowException: Bash command failed. The command returned a non-zero exit code 1.
[2025-04-06T02:33:35.758+0000] {local_task_job_runner.py:266} INFO - Task exited with return code 1
[2025-04-06T02:33:35.800+0000] {taskinstance.py:3901} INFO - 0 downstream tasks scheduled from follow-on schedule check
[2025-04-06T02:33:35.803+0000] {local_task_job_runner.py:245} INFO - ::endgroup::
