[2025-04-05T19:18:48.969+0000] {local_task_job_runner.py:123} INFO - ::group::Pre task execution logs
[2025-04-05T19:18:49.009+0000] {taskinstance.py:2614} INFO - Dependencies all met for dep_context=non-requeueable deps ti=<TaskInstance: fetch_and_store_data.trigger_dbt_run manual__2025-04-05T18:58:45.323254+00:00 [queued]>
[2025-04-05T19:18:49.029+0000] {taskinstance.py:2614} INFO - Dependencies all met for dep_context=requeueable deps ti=<TaskInstance: fetch_and_store_data.trigger_dbt_run manual__2025-04-05T18:58:45.323254+00:00 [queued]>
[2025-04-05T19:18:49.030+0000] {taskinstance.py:2867} INFO - Starting attempt 3 of 2
[2025-04-05T19:18:49.083+0000] {taskinstance.py:2890} INFO - Executing <Task(BashOperator): trigger_dbt_run> on 2025-04-05 18:58:45.323254+00:00
[2025-04-05T19:18:49.088+0000] {standard_task_runner.py:72} INFO - Started process 75 to run task
[2025-04-05T19:18:49.093+0000] {standard_task_runner.py:104} INFO - Running: ['airflow', 'tasks', 'run', 'fetch_and_store_data', 'trigger_dbt_run', 'manual__2025-04-05T18:58:45.323254+00:00', '--job-id', '52', '--raw', '--subdir', 'DAGS_FOLDER/reverse_etl_dag.py', '--cfg-path', '/tmp/tmpbpqjsjyw']
[2025-04-05T19:18:49.097+0000] {standard_task_runner.py:105} INFO - Job 52: Subtask trigger_dbt_run
[2025-04-05T19:18:49.206+0000] {task_command.py:467} INFO - Running <TaskInstance: fetch_and_store_data.trigger_dbt_run manual__2025-04-05T18:58:45.323254+00:00 [running]> on host 830eaf47e7f8
[2025-04-05T19:18:49.361+0000] {taskinstance.py:3134} INFO - Exporting env vars: AIRFLOW_CTX_DAG_OWNER='airflow' AIRFLOW_CTX_DAG_ID='fetch_and_store_data' AIRFLOW_CTX_TASK_ID='trigger_dbt_run' AIRFLOW_CTX_EXECUTION_DATE='2025-04-05T18:58:45.323254+00:00' AIRFLOW_CTX_TRY_NUMBER='3' AIRFLOW_CTX_DAG_RUN_ID='manual__2025-04-05T18:58:45.323254+00:00'
[2025-04-05T19:18:49.363+0000] {taskinstance.py:732} INFO - ::endgroup::
[2025-04-05T19:18:49.401+0000] {subprocess.py:78} INFO - Tmp dir root location: /tmp
[2025-04-05T19:18:49.403+0000] {subprocess.py:88} INFO - Running command: ['/usr/bin/bash', '-c', ' cd /usr/local/airflow/dags/reverse_etl && dbt run']
[2025-04-05T19:18:49.414+0000] {subprocess.py:99} INFO - Output:
[2025-04-05T19:18:55.598+0000] {subprocess.py:106} INFO - [0m19:18:55  Running with dbt=1.9.4
[2025-04-05T19:18:56.362+0000] {subprocess.py:106} INFO - [0m19:18:56  Registered adapter: postgres=1.9.0
[2025-04-05T19:18:57.779+0000] {subprocess.py:106} INFO - [0m19:18:57  Found 1 model, 1 source, 434 macros
[2025-04-05T19:18:57.785+0000] {subprocess.py:106} INFO - [0m19:18:57
[2025-04-05T19:18:57.787+0000] {subprocess.py:106} INFO - [0m19:18:57  Concurrency: 2 threads (target='dev')
[2025-04-05T19:18:57.789+0000] {subprocess.py:106} INFO - [0m19:18:57
[2025-04-05T19:19:15.756+0000] {subprocess.py:106} INFO - [0m19:19:15  1 of 1 START sql table model aggregated.survival_rate .......................... [RUN]
[2025-04-05T19:19:20.718+0000] {subprocess.py:106} INFO - [0m19:19:20  1 of 1 ERROR creating sql table model aggregated.survival_rate ................. [[31mERROR[0m in 4.94s]
[2025-04-05T19:19:24.840+0000] {subprocess.py:106} INFO - [0m19:19:24
[2025-04-05T19:19:24.844+0000] {subprocess.py:106} INFO - [0m19:19:24  Finished running 1 table model in 0 hours 0 minutes and 27.05 seconds (27.05s).
[2025-04-05T19:19:25.035+0000] {subprocess.py:106} INFO - [0m19:19:25
[2025-04-05T19:19:25.037+0000] {subprocess.py:106} INFO - [0m19:19:25  [31mCompleted with 1 error, 0 partial successes, and 0 warnings:[0m
[2025-04-05T19:19:25.039+0000] {subprocess.py:106} INFO - [0m19:19:25
[2025-04-05T19:19:25.041+0000] {subprocess.py:106} INFO - [0m19:19:25    Database Error in model survival_rate (models/aggregated/survival_rate.sql)
[2025-04-05T19:19:25.041+0000] {subprocess.py:106} INFO -   relation "public.titanic" does not exist
[2025-04-05T19:19:25.042+0000] {subprocess.py:106} INFO -   LINE 14:     from "railway"."public"."titanic"
[2025-04-05T19:19:25.042+0000] {subprocess.py:106} INFO -                     ^
[2025-04-05T19:19:25.043+0000] {subprocess.py:106} INFO -   compiled code at target/run/reverse_etl/models/aggregated/survival_rate.sql
[2025-04-05T19:19:25.043+0000] {subprocess.py:106} INFO - [0m19:19:25
[2025-04-05T19:19:25.044+0000] {subprocess.py:106} INFO - [0m19:19:25  Done. PASS=0 WARN=0 ERROR=1 SKIP=0 TOTAL=1
[2025-04-05T19:19:28.144+0000] {subprocess.py:110} INFO - Command exited with return code 1
[2025-04-05T19:19:28.177+0000] {taskinstance.py:3313} ERROR - Task failed with exception
Traceback (most recent call last):
  File "/home/airflow/.local/lib/python3.12/site-packages/airflow/models/taskinstance.py", line 768, in _execute_task
    result = _execute_callable(context=context, **execute_callable_kwargs)
             ^^^^^^^^^^^^^^^^^^^^^^^^^^^^^^^^^^^^^^^^^^^^^^^^^^^^^^^^^^^^^
  File "/home/airflow/.local/lib/python3.12/site-packages/airflow/models/taskinstance.py", line 734, in _execute_callable
    return ExecutionCallableRunner(
           ^^^^^^^^^^^^^^^^^^^^^^^^
  File "/home/airflow/.local/lib/python3.12/site-packages/airflow/utils/operator_helpers.py", line 252, in run
    return self.func(*args, **kwargs)
           ^^^^^^^^^^^^^^^^^^^^^^^^^^
  File "/home/airflow/.local/lib/python3.12/site-packages/airflow/models/baseoperator.py", line 424, in wrapper
    return func(self, *args, **kwargs)
           ^^^^^^^^^^^^^^^^^^^^^^^^^^^
  File "/home/airflow/.local/lib/python3.12/site-packages/airflow/operators/bash.py", line 276, in execute
    raise AirflowException(
airflow.exceptions.AirflowException: Bash command failed. The command returned a non-zero exit code 1.
[2025-04-05T19:19:28.190+0000] {taskinstance.py:1226} INFO - Marking task as FAILED. dag_id=fetch_and_store_data, task_id=trigger_dbt_run, run_id=manual__2025-04-05T18:58:45.323254+00:00, execution_date=20250405T185845, start_date=20250405T191849, end_date=20250405T191928
[2025-04-05T19:19:28.310+0000] {taskinstance.py:341} INFO - ::group::Post task execution logs
[2025-04-05T19:19:28.311+0000] {standard_task_runner.py:124} ERROR - Failed to execute job 52 for task trigger_dbt_run (Bash command failed. The command returned a non-zero exit code 1.; 75)
Traceback (most recent call last):
  File "/home/airflow/.local/lib/python3.12/site-packages/airflow/task/task_runner/standard_task_runner.py", line 117, in _start_by_fork
    ret = args.func(args, dag=self.dag)
          ^^^^^^^^^^^^^^^^^^^^^^^^^^^^^
  File "/home/airflow/.local/lib/python3.12/site-packages/airflow/cli/cli_config.py", line 49, in command
    return func(*args, **kwargs)
           ^^^^^^^^^^^^^^^^^^^^^
  File "/home/airflow/.local/lib/python3.12/site-packages/airflow/utils/cli.py", line 116, in wrapper
    return f(*args, **kwargs)
           ^^^^^^^^^^^^^^^^^^
  File "/home/airflow/.local/lib/python3.12/site-packages/airflow/cli/commands/task_command.py", line 483, in task_run
    task_return_code = _run_task_by_selected_method(args, _dag, ti)
                       ^^^^^^^^^^^^^^^^^^^^^^^^^^^^^^^^^^^^^^^^^^^^
  File "/home/airflow/.local/lib/python3.12/site-packages/airflow/cli/commands/task_command.py", line 256, in _run_task_by_selected_method
    return _run_raw_task(args, ti)
           ^^^^^^^^^^^^^^^^^^^^^^^
  File "/home/airflow/.local/lib/python3.12/site-packages/airflow/cli/commands/task_command.py", line 341, in _run_raw_task
    return ti._run_raw_task(
           ^^^^^^^^^^^^^^^^^
  File "/home/airflow/.local/lib/python3.12/site-packages/airflow/utils/session.py", line 97, in wrapper
    return func(*args, session=session, **kwargs)
           ^^^^^^^^^^^^^^^^^^^^^^^^^^^^^^^^^^^^^^
  File "/home/airflow/.local/lib/python3.12/site-packages/airflow/models/taskinstance.py", line 3006, in _run_raw_task
    return _run_raw_task(
           ^^^^^^^^^^^^^^
  File "/home/airflow/.local/lib/python3.12/site-packages/airflow/models/taskinstance.py", line 274, in _run_raw_task
    TaskInstance._execute_task_with_callbacks(
  File "/home/airflow/.local/lib/python3.12/site-packages/airflow/models/taskinstance.py", line 3161, in _execute_task_with_callbacks
    result = self._execute_task(context, task_orig)
             ^^^^^^^^^^^^^^^^^^^^^^^^^^^^^^^^^^^^^^
  File "/home/airflow/.local/lib/python3.12/site-packages/airflow/models/taskinstance.py", line 3185, in _execute_task
    return _execute_task(self, context, task_orig)
           ^^^^^^^^^^^^^^^^^^^^^^^^^^^^^^^^^^^^^^^
  File "/home/airflow/.local/lib/python3.12/site-packages/airflow/models/taskinstance.py", line 768, in _execute_task
    result = _execute_callable(context=context, **execute_callable_kwargs)
             ^^^^^^^^^^^^^^^^^^^^^^^^^^^^^^^^^^^^^^^^^^^^^^^^^^^^^^^^^^^^^
  File "/home/airflow/.local/lib/python3.12/site-packages/airflow/models/taskinstance.py", line 734, in _execute_callable
    return ExecutionCallableRunner(
           ^^^^^^^^^^^^^^^^^^^^^^^^
  File "/home/airflow/.local/lib/python3.12/site-packages/airflow/utils/operator_helpers.py", line 252, in run
    return self.func(*args, **kwargs)
           ^^^^^^^^^^^^^^^^^^^^^^^^^^
  File "/home/airflow/.local/lib/python3.12/site-packages/airflow/models/baseoperator.py", line 424, in wrapper
    return func(self, *args, **kwargs)
           ^^^^^^^^^^^^^^^^^^^^^^^^^^^
  File "/home/airflow/.local/lib/python3.12/site-packages/airflow/operators/bash.py", line 276, in execute
    raise AirflowException(
airflow.exceptions.AirflowException: Bash command failed. The command returned a non-zero exit code 1.
[2025-04-05T19:19:28.347+0000] {local_task_job_runner.py:266} INFO - Task exited with return code 1
[2025-04-05T19:19:28.370+0000] {taskinstance.py:3901} INFO - 0 downstream tasks scheduled from follow-on schedule check
[2025-04-05T19:19:28.372+0000] {local_task_job_runner.py:245} INFO - ::endgroup::
