[2025-04-05T19:06:58.471+0000] {local_task_job_runner.py:123} INFO - ::group::Pre task execution logs
[2025-04-05T19:06:58.516+0000] {taskinstance.py:2614} INFO - Dependencies all met for dep_context=non-requeueable deps ti=<TaskInstance: fetch_and_store_data.trigger_dbt_run manual__2025-04-05T18:58:45.323254+00:00 [queued]>
[2025-04-05T19:06:58.542+0000] {taskinstance.py:2614} INFO - Dependencies all met for dep_context=requeueable deps ti=<TaskInstance: fetch_and_store_data.trigger_dbt_run manual__2025-04-05T18:58:45.323254+00:00 [queued]>
[2025-04-05T19:06:58.542+0000] {taskinstance.py:2867} INFO - Starting attempt 1 of 2
[2025-04-05T19:06:58.609+0000] {taskinstance.py:2890} INFO - Executing <Task(BashOperator): trigger_dbt_run> on 2025-04-05 18:58:45.323254+00:00
[2025-04-05T19:06:58.615+0000] {standard_task_runner.py:72} INFO - Started process 526 to run task
[2025-04-05T19:06:58.619+0000] {standard_task_runner.py:104} INFO - Running: ['airflow', 'tasks', 'run', 'fetch_and_store_data', 'trigger_dbt_run', 'manual__2025-04-05T18:58:45.323254+00:00', '--job-id', '47', '--raw', '--subdir', 'DAGS_FOLDER/reverse_etl_dag.py', '--cfg-path', '/tmp/tmpu479q9_s']
[2025-04-05T19:06:58.622+0000] {standard_task_runner.py:105} INFO - Job 47: Subtask trigger_dbt_run
[2025-04-05T19:06:58.759+0000] {task_command.py:467} INFO - Running <TaskInstance: fetch_and_store_data.trigger_dbt_run manual__2025-04-05T18:58:45.323254+00:00 [running]> on host 830eaf47e7f8
[2025-04-05T19:06:58.953+0000] {taskinstance.py:3134} INFO - Exporting env vars: AIRFLOW_CTX_DAG_OWNER='airflow' AIRFLOW_CTX_DAG_ID='fetch_and_store_data' AIRFLOW_CTX_TASK_ID='trigger_dbt_run' AIRFLOW_CTX_EXECUTION_DATE='2025-04-05T18:58:45.323254+00:00' AIRFLOW_CTX_TRY_NUMBER='1' AIRFLOW_CTX_DAG_RUN_ID='manual__2025-04-05T18:58:45.323254+00:00'
[2025-04-05T19:06:58.954+0000] {taskinstance.py:732} INFO - ::endgroup::
[2025-04-05T19:06:58.971+0000] {subprocess.py:78} INFO - Tmp dir root location: /tmp
[2025-04-05T19:06:58.973+0000] {subprocess.py:88} INFO - Running command: ['/usr/bin/bash', '-c', ' cd /usr/local/airflow/dags/reverse_etl && dbt run']
[2025-04-05T19:06:58.981+0000] {subprocess.py:99} INFO - Output:
[2025-04-05T19:07:02.017+0000] {subprocess.py:106} INFO - [0m19:07:02  Running with dbt=1.9.4
[2025-04-05T19:07:02.457+0000] {subprocess.py:106} INFO - [0m19:07:02  Registered adapter: postgres=1.9.0
[2025-04-05T19:07:03.444+0000] {subprocess.py:106} INFO - [0m19:07:03  Found 1 model, 1 source, 434 macros
[2025-04-05T19:07:03.452+0000] {subprocess.py:106} INFO - [0m19:07:03
[2025-04-05T19:07:03.454+0000] {subprocess.py:106} INFO - [0m19:07:03  Concurrency: 2 threads (target='dev')
[2025-04-05T19:07:03.455+0000] {subprocess.py:106} INFO - [0m19:07:03
[2025-04-05T19:07:14.275+0000] {subprocess.py:106} INFO - [0m19:07:14  1 of 1 START sql table model aggregated.survival_rate .......................... [RUN]
[2025-04-05T19:07:17.894+0000] {subprocess.py:106} INFO - [0m19:07:17  1 of 1 ERROR creating sql table model aggregated.survival_rate ................. [[31mERROR[0m in 3.61s]
[2025-04-05T19:07:21.194+0000] {subprocess.py:106} INFO - [0m19:07:21
[2025-04-05T19:07:21.195+0000] {subprocess.py:106} INFO - [0m19:07:21  Finished running 1 table model in 0 hours 0 minutes and 17.74 seconds (17.74s).
[2025-04-05T19:07:21.295+0000] {subprocess.py:106} INFO - [0m19:07:21
[2025-04-05T19:07:21.296+0000] {subprocess.py:106} INFO - [0m19:07:21  [31mCompleted with 1 error, 0 partial successes, and 0 warnings:[0m
[2025-04-05T19:07:21.298+0000] {subprocess.py:106} INFO - [0m19:07:21
[2025-04-05T19:07:21.300+0000] {subprocess.py:106} INFO - [0m19:07:21    Database Error in model survival_rate (models/aggregated/survival_rate.sql)
[2025-04-05T19:07:21.301+0000] {subprocess.py:106} INFO -   relation "public.titanic" does not exist
[2025-04-05T19:07:21.302+0000] {subprocess.py:106} INFO -   LINE 14:     from "railway"."public"."titanic"
[2025-04-05T19:07:21.302+0000] {subprocess.py:106} INFO -                     ^
[2025-04-05T19:07:21.303+0000] {subprocess.py:106} INFO -   compiled code at target/run/reverse_etl/models/aggregated/survival_rate.sql
[2025-04-05T19:07:21.304+0000] {subprocess.py:106} INFO - [0m19:07:21
[2025-04-05T19:07:21.305+0000] {subprocess.py:106} INFO - [0m19:07:21  Done. PASS=0 WARN=0 ERROR=1 SKIP=0 TOTAL=1
[2025-04-05T19:07:24.457+0000] {subprocess.py:110} INFO - Command exited with return code 1
[2025-04-05T19:07:24.482+0000] {taskinstance.py:3313} ERROR - Task failed with exception
Traceback (most recent call last):
  File "/home/airflow/.local/lib/python3.12/site-packages/airflow/models/taskinstance.py", line 768, in _execute_task
    result = _execute_callable(context=context, **execute_callable_kwargs)
             ^^^^^^^^^^^^^^^^^^^^^^^^^^^^^^^^^^^^^^^^^^^^^^^^^^^^^^^^^^^^^
  File "/home/airflow/.local/lib/python3.12/site-packages/airflow/models/taskinstance.py", line 734, in _execute_callable
    return ExecutionCallableRunner(
           ^^^^^^^^^^^^^^^^^^^^^^^^
  File "/home/airflow/.local/lib/python3.12/site-packages/airflow/utils/operator_helpers.py", line 252, in run
    return self.func(*args, **kwargs)
           ^^^^^^^^^^^^^^^^^^^^^^^^^^
  File "/home/airflow/.local/lib/python3.12/site-packages/airflow/models/baseoperator.py", line 424, in wrapper
    return func(self, *args, **kwargs)
           ^^^^^^^^^^^^^^^^^^^^^^^^^^^
  File "/home/airflow/.local/lib/python3.12/site-packages/airflow/operators/bash.py", line 276, in execute
    raise AirflowException(
airflow.exceptions.AirflowException: Bash command failed. The command returned a non-zero exit code 1.
[2025-04-05T19:07:24.496+0000] {taskinstance.py:1226} INFO - Marking task as UP_FOR_RETRY. dag_id=fetch_and_store_data, task_id=trigger_dbt_run, run_id=manual__2025-04-05T18:58:45.323254+00:00, execution_date=20250405T185845, start_date=20250405T190658, end_date=20250405T190724
[2025-04-05T19:07:24.634+0000] {taskinstance.py:341} INFO - ::group::Post task execution logs
[2025-04-05T19:07:24.636+0000] {standard_task_runner.py:124} ERROR - Failed to execute job 47 for task trigger_dbt_run (Bash command failed. The command returned a non-zero exit code 1.; 526)
Traceback (most recent call last):
  File "/home/airflow/.local/lib/python3.12/site-packages/airflow/task/task_runner/standard_task_runner.py", line 117, in _start_by_fork
    ret = args.func(args, dag=self.dag)
          ^^^^^^^^^^^^^^^^^^^^^^^^^^^^^
  File "/home/airflow/.local/lib/python3.12/site-packages/airflow/cli/cli_config.py", line 49, in command
    return func(*args, **kwargs)
           ^^^^^^^^^^^^^^^^^^^^^
  File "/home/airflow/.local/lib/python3.12/site-packages/airflow/utils/cli.py", line 116, in wrapper
    return f(*args, **kwargs)
           ^^^^^^^^^^^^^^^^^^
  File "/home/airflow/.local/lib/python3.12/site-packages/airflow/cli/commands/task_command.py", line 483, in task_run
    task_return_code = _run_task_by_selected_method(args, _dag, ti)
                       ^^^^^^^^^^^^^^^^^^^^^^^^^^^^^^^^^^^^^^^^^^^^
  File "/home/airflow/.local/lib/python3.12/site-packages/airflow/cli/commands/task_command.py", line 256, in _run_task_by_selected_method
    return _run_raw_task(args, ti)
           ^^^^^^^^^^^^^^^^^^^^^^^
  File "/home/airflow/.local/lib/python3.12/site-packages/airflow/cli/commands/task_command.py", line 341, in _run_raw_task
    return ti._run_raw_task(
           ^^^^^^^^^^^^^^^^^
  File "/home/airflow/.local/lib/python3.12/site-packages/airflow/utils/session.py", line 97, in wrapper
    return func(*args, session=session, **kwargs)
           ^^^^^^^^^^^^^^^^^^^^^^^^^^^^^^^^^^^^^^
  File "/home/airflow/.local/lib/python3.12/site-packages/airflow/models/taskinstance.py", line 3006, in _run_raw_task
    return _run_raw_task(
           ^^^^^^^^^^^^^^
  File "/home/airflow/.local/lib/python3.12/site-packages/airflow/models/taskinstance.py", line 274, in _run_raw_task
    TaskInstance._execute_task_with_callbacks(
  File "/home/airflow/.local/lib/python3.12/site-packages/airflow/models/taskinstance.py", line 3161, in _execute_task_with_callbacks
    result = self._execute_task(context, task_orig)
             ^^^^^^^^^^^^^^^^^^^^^^^^^^^^^^^^^^^^^^
  File "/home/airflow/.local/lib/python3.12/site-packages/airflow/models/taskinstance.py", line 3185, in _execute_task
    return _execute_task(self, context, task_orig)
           ^^^^^^^^^^^^^^^^^^^^^^^^^^^^^^^^^^^^^^^
  File "/home/airflow/.local/lib/python3.12/site-packages/airflow/models/taskinstance.py", line 768, in _execute_task
    result = _execute_callable(context=context, **execute_callable_kwargs)
             ^^^^^^^^^^^^^^^^^^^^^^^^^^^^^^^^^^^^^^^^^^^^^^^^^^^^^^^^^^^^^
  File "/home/airflow/.local/lib/python3.12/site-packages/airflow/models/taskinstance.py", line 734, in _execute_callable
    return ExecutionCallableRunner(
           ^^^^^^^^^^^^^^^^^^^^^^^^
  File "/home/airflow/.local/lib/python3.12/site-packages/airflow/utils/operator_helpers.py", line 252, in run
    return self.func(*args, **kwargs)
           ^^^^^^^^^^^^^^^^^^^^^^^^^^
  File "/home/airflow/.local/lib/python3.12/site-packages/airflow/models/baseoperator.py", line 424, in wrapper
    return func(self, *args, **kwargs)
           ^^^^^^^^^^^^^^^^^^^^^^^^^^^
  File "/home/airflow/.local/lib/python3.12/site-packages/airflow/operators/bash.py", line 276, in execute
    raise AirflowException(
airflow.exceptions.AirflowException: Bash command failed. The command returned a non-zero exit code 1.
[2025-04-05T19:07:24.688+0000] {local_task_job_runner.py:266} INFO - Task exited with return code 1
[2025-04-05T19:07:24.734+0000] {taskinstance.py:3901} INFO - 0 downstream tasks scheduled from follow-on schedule check
[2025-04-05T19:07:24.737+0000] {local_task_job_runner.py:245} INFO - ::endgroup::
