[2025-04-05T17:55:06.497+0000] {local_task_job_runner.py:123} INFO - ::group::Pre task execution logs
[2025-04-05T17:55:06.540+0000] {taskinstance.py:2614} INFO - Dependencies all met for dep_context=non-requeueable deps ti=<TaskInstance: fetch_and_store_data.retriving_data_from_postgres manual__2025-04-05T17:29:27.384414+00:00 [queued]>
[2025-04-05T17:55:06.567+0000] {taskinstance.py:2614} INFO - Dependencies all met for dep_context=requeueable deps ti=<TaskInstance: fetch_and_store_data.retriving_data_from_postgres manual__2025-04-05T17:29:27.384414+00:00 [queued]>
[2025-04-05T17:55:06.567+0000] {taskinstance.py:2867} INFO - Starting attempt 1 of 2
[2025-04-05T17:55:06.628+0000] {taskinstance.py:2890} INFO - Executing <Task(PythonOperator): retriving_data_from_postgres> on 2025-04-05 17:29:27.384414+00:00
[2025-04-05T17:55:06.636+0000] {standard_task_runner.py:72} INFO - Started process 405 to run task
[2025-04-05T17:55:06.640+0000] {standard_task_runner.py:104} INFO - Running: ['airflow', 'tasks', 'run', 'fetch_and_store_data', 'retriving_data_from_postgres', 'manual__2025-04-05T17:29:27.384414+00:00', '--job-id', '19', '--raw', '--subdir', 'DAGS_FOLDER/reverse_etl_dag.py', '--cfg-path', '/tmp/tmpjmt9muhj']
[2025-04-05T17:55:06.643+0000] {standard_task_runner.py:105} INFO - Job 19: Subtask retriving_data_from_postgres
[2025-04-05T17:55:06.768+0000] {task_command.py:467} INFO - Running <TaskInstance: fetch_and_store_data.retriving_data_from_postgres manual__2025-04-05T17:29:27.384414+00:00 [running]> on host 20f80019eeb6
[2025-04-05T17:55:06.976+0000] {taskinstance.py:3134} INFO - Exporting env vars: AIRFLOW_CTX_DAG_OWNER='airflow' AIRFLOW_CTX_DAG_ID='fetch_and_store_data' AIRFLOW_CTX_TASK_ID='retriving_data_from_postgres' AIRFLOW_CTX_EXECUTION_DATE='2025-04-05T17:29:27.384414+00:00' AIRFLOW_CTX_TRY_NUMBER='1' AIRFLOW_CTX_DAG_RUN_ID='manual__2025-04-05T17:29:27.384414+00:00'
[2025-04-05T17:55:06.978+0000] {taskinstance.py:732} INFO - ::endgroup::
[2025-04-05T17:55:09.579+0000] {logging_mixin.py:190} INFO - Access token retrieved: eyJhbGciOiJSUzI1NiIsInR5cCIgOiAiSldUIiwia2lkIiA6ICJ6Z1BPdmhDSC1Ic21OQnhhV3lnLU11dlF6dHJERTBDSEJHZDB2MVh0Vnk0In0.eyJleHAiOjE3NDM4NzY2MDksImlhdCI6MTc0Mzg3NTcwOSwianRpIjoiYmI0ZWFjOWUtYzdhYi00OTVhLTgyODctNzRhMzBkYjk1OGUwIiwiaXNzIjoiaHR0cHM6Ly9jbG91ZC5haXJieXRlLmNvbS9hdXRoL3JlYWxtcy9fYWlyYnl0ZS1hcHBsaWNhdGlvbi1jbGllbnRzIiwiYXVkIjoiYWNjb3VudCIsInN1YiI6IjIzMzZjOWQyLTQ4OTUtNGY5NS04NDJiLTRjZjE2NTg1YmUxMyIsInR5cCI6IkJlYXJlciIsImF6cCI6IjE0MWZkYTI2LTViODctNDZjYi1iODZlLTdhYTQxNjZiYWJhZCIsImFjciI6IjEiLCJyZWFsbV9hY2Nlc3MiOnsicm9sZXMiOlsib2ZmbGluZV9hY2Nlc3MiLCJ1bWFfYXV0aG9yaXphdGlvbiIsImRlZmF1bHQtcm9sZXMtX2FpcmJ5dGUtYXBwbGljYXRpb24tY2xpZW50cyJdfSwicmVzb3VyY2VfYWNjZXNzIjp7ImFjY291bnQiOnsicm9sZXMiOlsibWFuYWdlLWFjY291bnQiLCJtYW5hZ2UtYWNjb3VudC1saW5rcyIsInZpZXctcHJvZmlsZSJdfX0sInNjb3BlIjoib3BlbmlkIGVtYWlsIHByb2ZpbGUiLCJlbWFpbF92ZXJpZmllZCI6ZmFsc2UsImNsaWVudEhvc3QiOiIxNzIuMjMuMy42NyIsInVzZXJfaWQiOiIyMzM2YzlkMi00ODk1LTRmOTUtODQyYi00Y2YxNjU4NWJlMTMiLCJwcmVmZXJyZWRfdXNlcm5hbWUiOiJzZXJ2aWNlLWFjY291bnQtMTQxZmRhMjYtNWI4Ny00NmNiLWI4NmUtN2FhNDE2NmJhYmFkIiwiY2xpZW50QWRkcmVzcyI6IjE3Mi4yMy4zLjY3IiwiY2xpZW50X2lkIjoiMTQxZmRhMjYtNWI4Ny00NmNiLWI4NmUtN2FhNDE2NmJhYmFkIn0.jjlseloVyESo8mo81AJzePLZ9JUBL7amV9zGSTrs_zEoHtXAp48bCWi8y6AdGVIMIIzz01Y0_iW_3IHvMJUgEwh5lGw4IBPxfjG2sYLRapGXxP4GSYnHg2fBMoOXmQX4LIIrxo9KiwtnbfMODQwQazkCorkV-7ioMpegNBGxMNMUWgOEK0GGPuZyDvvpG3Yi2h4cuijgVBTc2RSVUGmBmwh-STYjRyEQyIH4MQ9Cv26VXTkLRR0L4c5PRJ-vCJVEt8IDcZdL2RAAy1b3PFJpTRXuS7GholPhfjwKcM56JyX30xSE3Mlctnp6e_5Yn6BpgK_PiYbYxGz7xBsj-ZYKUw
[2025-04-05T17:55:10.429+0000] {taskinstance.py:3313} ERROR - Task failed with exception
Traceback (most recent call last):
  File "/home/airflow/.local/lib/python3.12/site-packages/airflow/models/taskinstance.py", line 768, in _execute_task
    result = _execute_callable(context=context, **execute_callable_kwargs)
             ^^^^^^^^^^^^^^^^^^^^^^^^^^^^^^^^^^^^^^^^^^^^^^^^^^^^^^^^^^^^^
  File "/home/airflow/.local/lib/python3.12/site-packages/airflow/models/taskinstance.py", line 734, in _execute_callable
    return ExecutionCallableRunner(
           ^^^^^^^^^^^^^^^^^^^^^^^^
  File "/home/airflow/.local/lib/python3.12/site-packages/airflow/utils/operator_helpers.py", line 252, in run
    return self.func(*args, **kwargs)
           ^^^^^^^^^^^^^^^^^^^^^^^^^^
  File "/home/airflow/.local/lib/python3.12/site-packages/airflow/models/baseoperator.py", line 424, in wrapper
    return func(self, *args, **kwargs)
           ^^^^^^^^^^^^^^^^^^^^^^^^^^^
  File "/home/airflow/.local/lib/python3.12/site-packages/airflow/operators/python.py", line 238, in execute
    return_value = self.execute_callable()
                   ^^^^^^^^^^^^^^^^^^^^^^^
  File "/home/airflow/.local/lib/python3.12/site-packages/airflow/operators/python.py", line 256, in execute_callable
    return runner.run(*self.op_args, **self.op_kwargs)
           ^^^^^^^^^^^^^^^^^^^^^^^^^^^^^^^^^^^^^^^^^^^
  File "/home/airflow/.local/lib/python3.12/site-packages/airflow/utils/operator_helpers.py", line 252, in run
    return self.func(*args, **kwargs)
           ^^^^^^^^^^^^^^^^^^^^^^^^^^
  File "/usr/local/airflow/dags/reverse_etl_dag.py", line 62, in trigger_airbyte_sync
    raise AirflowException(
airflow.exceptions.AirflowException: Failed to trigger Airbyte connection. Response: {"status":409,"type":"https://reference.airbyte.com/reference/errors#try-again-later","title":"try-again-later","detail":"Please try again later.","documentationUrl":null,"data":{"message":"A sync is already running for: d22193d6-ce77-4ca2-b336-03826b5174c3"}}
[2025-04-05T17:55:10.449+0000] {taskinstance.py:1226} INFO - Marking task as UP_FOR_RETRY. dag_id=fetch_and_store_data, task_id=retriving_data_from_postgres, run_id=manual__2025-04-05T17:29:27.384414+00:00, execution_date=20250405T172927, start_date=20250405T175506, end_date=20250405T175510
[2025-04-05T17:55:10.565+0000] {taskinstance.py:341} INFO - ::group::Post task execution logs
[2025-04-05T17:55:10.566+0000] {standard_task_runner.py:124} ERROR - Failed to execute job 19 for task retriving_data_from_postgres (Failed to trigger Airbyte connection. Response: {"status":409,"type":"https://reference.airbyte.com/reference/errors#try-again-later","title":"try-again-later","detail":"Please try again later.","documentationUrl":null,"data":{"message":"A sync is already running for: d22193d6-ce77-4ca2-b336-03826b5174c3"}}; 405)
Traceback (most recent call last):
  File "/home/airflow/.local/lib/python3.12/site-packages/airflow/task/task_runner/standard_task_runner.py", line 117, in _start_by_fork
    ret = args.func(args, dag=self.dag)
          ^^^^^^^^^^^^^^^^^^^^^^^^^^^^^
  File "/home/airflow/.local/lib/python3.12/site-packages/airflow/cli/cli_config.py", line 49, in command
    return func(*args, **kwargs)
           ^^^^^^^^^^^^^^^^^^^^^
  File "/home/airflow/.local/lib/python3.12/site-packages/airflow/utils/cli.py", line 116, in wrapper
    return f(*args, **kwargs)
           ^^^^^^^^^^^^^^^^^^
  File "/home/airflow/.local/lib/python3.12/site-packages/airflow/cli/commands/task_command.py", line 483, in task_run
    task_return_code = _run_task_by_selected_method(args, _dag, ti)
                       ^^^^^^^^^^^^^^^^^^^^^^^^^^^^^^^^^^^^^^^^^^^^
  File "/home/airflow/.local/lib/python3.12/site-packages/airflow/cli/commands/task_command.py", line 256, in _run_task_by_selected_method
    return _run_raw_task(args, ti)
           ^^^^^^^^^^^^^^^^^^^^^^^
  File "/home/airflow/.local/lib/python3.12/site-packages/airflow/cli/commands/task_command.py", line 341, in _run_raw_task
    return ti._run_raw_task(
           ^^^^^^^^^^^^^^^^^
  File "/home/airflow/.local/lib/python3.12/site-packages/airflow/utils/session.py", line 97, in wrapper
    return func(*args, session=session, **kwargs)
           ^^^^^^^^^^^^^^^^^^^^^^^^^^^^^^^^^^^^^^
  File "/home/airflow/.local/lib/python3.12/site-packages/airflow/models/taskinstance.py", line 3006, in _run_raw_task
    return _run_raw_task(
           ^^^^^^^^^^^^^^
  File "/home/airflow/.local/lib/python3.12/site-packages/airflow/models/taskinstance.py", line 274, in _run_raw_task
    TaskInstance._execute_task_with_callbacks(
  File "/home/airflow/.local/lib/python3.12/site-packages/airflow/models/taskinstance.py", line 3161, in _execute_task_with_callbacks
    result = self._execute_task(context, task_orig)
             ^^^^^^^^^^^^^^^^^^^^^^^^^^^^^^^^^^^^^^
  File "/home/airflow/.local/lib/python3.12/site-packages/airflow/models/taskinstance.py", line 3185, in _execute_task
    return _execute_task(self, context, task_orig)
           ^^^^^^^^^^^^^^^^^^^^^^^^^^^^^^^^^^^^^^^
  File "/home/airflow/.local/lib/python3.12/site-packages/airflow/models/taskinstance.py", line 768, in _execute_task
    result = _execute_callable(context=context, **execute_callable_kwargs)
             ^^^^^^^^^^^^^^^^^^^^^^^^^^^^^^^^^^^^^^^^^^^^^^^^^^^^^^^^^^^^^
  File "/home/airflow/.local/lib/python3.12/site-packages/airflow/models/taskinstance.py", line 734, in _execute_callable
    return ExecutionCallableRunner(
           ^^^^^^^^^^^^^^^^^^^^^^^^
  File "/home/airflow/.local/lib/python3.12/site-packages/airflow/utils/operator_helpers.py", line 252, in run
    return self.func(*args, **kwargs)
           ^^^^^^^^^^^^^^^^^^^^^^^^^^
  File "/home/airflow/.local/lib/python3.12/site-packages/airflow/models/baseoperator.py", line 424, in wrapper
    return func(self, *args, **kwargs)
           ^^^^^^^^^^^^^^^^^^^^^^^^^^^
  File "/home/airflow/.local/lib/python3.12/site-packages/airflow/operators/python.py", line 238, in execute
    return_value = self.execute_callable()
                   ^^^^^^^^^^^^^^^^^^^^^^^
  File "/home/airflow/.local/lib/python3.12/site-packages/airflow/operators/python.py", line 256, in execute_callable
    return runner.run(*self.op_args, **self.op_kwargs)
           ^^^^^^^^^^^^^^^^^^^^^^^^^^^^^^^^^^^^^^^^^^^
  File "/home/airflow/.local/lib/python3.12/site-packages/airflow/utils/operator_helpers.py", line 252, in run
    return self.func(*args, **kwargs)
           ^^^^^^^^^^^^^^^^^^^^^^^^^^
  File "/usr/local/airflow/dags/reverse_etl_dag.py", line 62, in trigger_airbyte_sync
    raise AirflowException(
airflow.exceptions.AirflowException: Failed to trigger Airbyte connection. Response: {"status":409,"type":"https://reference.airbyte.com/reference/errors#try-again-later","title":"try-again-later","detail":"Please try again later.","documentationUrl":null,"data":{"message":"A sync is already running for: d22193d6-ce77-4ca2-b336-03826b5174c3"}}
[2025-04-05T17:55:10.597+0000] {local_task_job_runner.py:266} INFO - Task exited with return code 1
[2025-04-05T17:55:10.642+0000] {taskinstance.py:3901} INFO - 0 downstream tasks scheduled from follow-on schedule check
[2025-04-05T17:55:10.644+0000] {local_task_job_runner.py:245} INFO - ::endgroup::
