[2025-04-05T18:56:10.130+0000] {local_task_job_runner.py:123} INFO - ::group::Pre task execution logs
[2025-04-05T18:56:10.184+0000] {taskinstance.py:2614} INFO - Dependencies all met for dep_context=non-requeueable deps ti=<TaskInstance: fetch_and_store_data.trigger_dbt_run manual__2025-04-05T18:46:06.427208+00:00 [queued]>
[2025-04-05T18:56:10.213+0000] {taskinstance.py:2614} INFO - Dependencies all met for dep_context=requeueable deps ti=<TaskInstance: fetch_and_store_data.trigger_dbt_run manual__2025-04-05T18:46:06.427208+00:00 [queued]>
[2025-04-05T18:56:10.213+0000] {taskinstance.py:2867} INFO - Starting attempt 1 of 2
[2025-04-05T18:56:10.284+0000] {taskinstance.py:2890} INFO - Executing <Task(BashOperator): trigger_dbt_run> on 2025-04-05 18:46:06.427208+00:00
[2025-04-05T18:56:10.290+0000] {standard_task_runner.py:72} INFO - Started process 425 to run task
[2025-04-05T18:56:10.295+0000] {standard_task_runner.py:104} INFO - Running: ['airflow', 'tasks', 'run', 'fetch_and_store_data', 'trigger_dbt_run', 'manual__2025-04-05T18:46:06.427208+00:00', '--job-id', '42', '--raw', '--subdir', 'DAGS_FOLDER/reverse_etl_dag.py', '--cfg-path', '/tmp/tmpktcixx74']
[2025-04-05T18:56:10.298+0000] {standard_task_runner.py:105} INFO - Job 42: Subtask trigger_dbt_run
[2025-04-05T18:56:10.438+0000] {task_command.py:467} INFO - Running <TaskInstance: fetch_and_store_data.trigger_dbt_run manual__2025-04-05T18:46:06.427208+00:00 [running]> on host 830eaf47e7f8
[2025-04-05T18:56:10.639+0000] {taskinstance.py:3134} INFO - Exporting env vars: AIRFLOW_CTX_DAG_OWNER='airflow' AIRFLOW_CTX_DAG_ID='fetch_and_store_data' AIRFLOW_CTX_TASK_ID='trigger_dbt_run' AIRFLOW_CTX_EXECUTION_DATE='2025-04-05T18:46:06.427208+00:00' AIRFLOW_CTX_TRY_NUMBER='1' AIRFLOW_CTX_DAG_RUN_ID='manual__2025-04-05T18:46:06.427208+00:00'
[2025-04-05T18:56:10.641+0000] {taskinstance.py:732} INFO - ::endgroup::
[2025-04-05T18:56:10.663+0000] {subprocess.py:78} INFO - Tmp dir root location: /tmp
[2025-04-05T18:56:10.664+0000] {subprocess.py:88} INFO - Running command: ['/usr/bin/bash', '-c', ' cd /usr/local/airflow/dags/reverse_etl && dbt run']
[2025-04-05T18:56:10.676+0000] {subprocess.py:99} INFO - Output:
[2025-04-05T18:56:15.248+0000] {subprocess.py:106} INFO - [0m18:56:15  Running with dbt=1.9.4
[2025-04-05T18:56:15.978+0000] {subprocess.py:106} INFO - [0m18:56:15  Registered adapter: postgres=1.9.0
[2025-04-05T18:56:17.110+0000] {subprocess.py:106} INFO - [0m18:56:17  Found 1 model, 1 source, 434 macros
[2025-04-05T18:56:17.117+0000] {subprocess.py:106} INFO - [0m18:56:17
[2025-04-05T18:56:17.118+0000] {subprocess.py:106} INFO - [0m18:56:17  Concurrency: 2 threads (target='dev')
[2025-04-05T18:56:17.119+0000] {subprocess.py:106} INFO - [0m18:56:17
[2025-04-05T18:56:32.773+0000] {subprocess.py:106} INFO - [0m18:56:32  1 of 1 START sql table model aggregated.survival_rate .......................... [RUN]
[2025-04-05T18:56:36.865+0000] {subprocess.py:106} INFO - [0m18:56:36  1 of 1 ERROR creating sql table model aggregated.survival_rate ................. [[31mERROR[0m in 4.08s]
[2025-04-05T18:56:40.615+0000] {subprocess.py:106} INFO - [0m18:56:40
[2025-04-05T18:56:40.616+0000] {subprocess.py:106} INFO - [0m18:56:40  Finished running 1 table model in 0 hours 0 minutes and 23.49 seconds (23.49s).
[2025-04-05T18:56:40.707+0000] {subprocess.py:106} INFO - [0m18:56:40
[2025-04-05T18:56:40.708+0000] {subprocess.py:106} INFO - [0m18:56:40  [31mCompleted with 1 error, 0 partial successes, and 0 warnings:[0m
[2025-04-05T18:56:40.709+0000] {subprocess.py:106} INFO - [0m18:56:40
[2025-04-05T18:56:40.711+0000] {subprocess.py:106} INFO - [0m18:56:40    Database Error in model survival_rate (models/aggregated/survival_rate.sql)
[2025-04-05T18:56:40.712+0000] {subprocess.py:106} INFO -   syntax error at or near "s"
[2025-04-05T18:56:40.712+0000] {subprocess.py:106} INFO -   LINE 27: s
[2025-04-05T18:56:40.713+0000] {subprocess.py:106} INFO -            ^
[2025-04-05T18:56:40.714+0000] {subprocess.py:106} INFO -   compiled code at target/run/reverse_etl/models/aggregated/survival_rate.sql
[2025-04-05T18:56:40.714+0000] {subprocess.py:106} INFO - [0m18:56:40
[2025-04-05T18:56:40.715+0000] {subprocess.py:106} INFO - [0m18:56:40  Done. PASS=0 WARN=0 ERROR=1 SKIP=0 TOTAL=1
[2025-04-05T18:56:43.827+0000] {subprocess.py:110} INFO - Command exited with return code 1
[2025-04-05T18:56:43.848+0000] {taskinstance.py:3313} ERROR - Task failed with exception
Traceback (most recent call last):
  File "/home/airflow/.local/lib/python3.12/site-packages/airflow/models/taskinstance.py", line 768, in _execute_task
    result = _execute_callable(context=context, **execute_callable_kwargs)
             ^^^^^^^^^^^^^^^^^^^^^^^^^^^^^^^^^^^^^^^^^^^^^^^^^^^^^^^^^^^^^
  File "/home/airflow/.local/lib/python3.12/site-packages/airflow/models/taskinstance.py", line 734, in _execute_callable
    return ExecutionCallableRunner(
           ^^^^^^^^^^^^^^^^^^^^^^^^
  File "/home/airflow/.local/lib/python3.12/site-packages/airflow/utils/operator_helpers.py", line 252, in run
    return self.func(*args, **kwargs)
           ^^^^^^^^^^^^^^^^^^^^^^^^^^
  File "/home/airflow/.local/lib/python3.12/site-packages/airflow/models/baseoperator.py", line 424, in wrapper
    return func(self, *args, **kwargs)
           ^^^^^^^^^^^^^^^^^^^^^^^^^^^
  File "/home/airflow/.local/lib/python3.12/site-packages/airflow/operators/bash.py", line 276, in execute
    raise AirflowException(
airflow.exceptions.AirflowException: Bash command failed. The command returned a non-zero exit code 1.
[2025-04-05T18:56:43.863+0000] {taskinstance.py:1226} INFO - Marking task as UP_FOR_RETRY. dag_id=fetch_and_store_data, task_id=trigger_dbt_run, run_id=manual__2025-04-05T18:46:06.427208+00:00, execution_date=20250405T184606, start_date=20250405T185610, end_date=20250405T185643
[2025-04-05T18:56:43.974+0000] {taskinstance.py:341} INFO - ::group::Post task execution logs
[2025-04-05T18:56:43.976+0000] {standard_task_runner.py:124} ERROR - Failed to execute job 42 for task trigger_dbt_run (Bash command failed. The command returned a non-zero exit code 1.; 425)
Traceback (most recent call last):
  File "/home/airflow/.local/lib/python3.12/site-packages/airflow/task/task_runner/standard_task_runner.py", line 117, in _start_by_fork
    ret = args.func(args, dag=self.dag)
          ^^^^^^^^^^^^^^^^^^^^^^^^^^^^^
  File "/home/airflow/.local/lib/python3.12/site-packages/airflow/cli/cli_config.py", line 49, in command
    return func(*args, **kwargs)
           ^^^^^^^^^^^^^^^^^^^^^
  File "/home/airflow/.local/lib/python3.12/site-packages/airflow/utils/cli.py", line 116, in wrapper
    return f(*args, **kwargs)
           ^^^^^^^^^^^^^^^^^^
  File "/home/airflow/.local/lib/python3.12/site-packages/airflow/cli/commands/task_command.py", line 483, in task_run
    task_return_code = _run_task_by_selected_method(args, _dag, ti)
                       ^^^^^^^^^^^^^^^^^^^^^^^^^^^^^^^^^^^^^^^^^^^^
  File "/home/airflow/.local/lib/python3.12/site-packages/airflow/cli/commands/task_command.py", line 256, in _run_task_by_selected_method
    return _run_raw_task(args, ti)
           ^^^^^^^^^^^^^^^^^^^^^^^
  File "/home/airflow/.local/lib/python3.12/site-packages/airflow/cli/commands/task_command.py", line 341, in _run_raw_task
    return ti._run_raw_task(
           ^^^^^^^^^^^^^^^^^
  File "/home/airflow/.local/lib/python3.12/site-packages/airflow/utils/session.py", line 97, in wrapper
    return func(*args, session=session, **kwargs)
           ^^^^^^^^^^^^^^^^^^^^^^^^^^^^^^^^^^^^^^
  File "/home/airflow/.local/lib/python3.12/site-packages/airflow/models/taskinstance.py", line 3006, in _run_raw_task
    return _run_raw_task(
           ^^^^^^^^^^^^^^
  File "/home/airflow/.local/lib/python3.12/site-packages/airflow/models/taskinstance.py", line 274, in _run_raw_task
    TaskInstance._execute_task_with_callbacks(
  File "/home/airflow/.local/lib/python3.12/site-packages/airflow/models/taskinstance.py", line 3161, in _execute_task_with_callbacks
    result = self._execute_task(context, task_orig)
             ^^^^^^^^^^^^^^^^^^^^^^^^^^^^^^^^^^^^^^
  File "/home/airflow/.local/lib/python3.12/site-packages/airflow/models/taskinstance.py", line 3185, in _execute_task
    return _execute_task(self, context, task_orig)
           ^^^^^^^^^^^^^^^^^^^^^^^^^^^^^^^^^^^^^^^
  File "/home/airflow/.local/lib/python3.12/site-packages/airflow/models/taskinstance.py", line 768, in _execute_task
    result = _execute_callable(context=context, **execute_callable_kwargs)
             ^^^^^^^^^^^^^^^^^^^^^^^^^^^^^^^^^^^^^^^^^^^^^^^^^^^^^^^^^^^^^
  File "/home/airflow/.local/lib/python3.12/site-packages/airflow/models/taskinstance.py", line 734, in _execute_callable
    return ExecutionCallableRunner(
           ^^^^^^^^^^^^^^^^^^^^^^^^
  File "/home/airflow/.local/lib/python3.12/site-packages/airflow/utils/operator_helpers.py", line 252, in run
    return self.func(*args, **kwargs)
           ^^^^^^^^^^^^^^^^^^^^^^^^^^
  File "/home/airflow/.local/lib/python3.12/site-packages/airflow/models/baseoperator.py", line 424, in wrapper
    return func(self, *args, **kwargs)
           ^^^^^^^^^^^^^^^^^^^^^^^^^^^
  File "/home/airflow/.local/lib/python3.12/site-packages/airflow/operators/bash.py", line 276, in execute
    raise AirflowException(
airflow.exceptions.AirflowException: Bash command failed. The command returned a non-zero exit code 1.
[2025-04-05T18:56:44.002+0000] {local_task_job_runner.py:266} INFO - Task exited with return code 1
[2025-04-05T18:56:44.086+0000] {taskinstance.py:3901} INFO - 0 downstream tasks scheduled from follow-on schedule check
[2025-04-05T18:56:44.089+0000] {local_task_job_runner.py:245} INFO - ::endgroup::
