[2025-04-05T17:54:55.666+0000] {local_task_job_runner.py:123} INFO - ::group::Pre task execution logs
[2025-04-05T17:54:55.721+0000] {taskinstance.py:2614} INFO - Dependencies all met for dep_context=non-requeueable deps ti=<TaskInstance: fetch_and_store_data.retriving_data_from_postgres manual__2025-04-05T17:20:14.529744+00:00 [queued]>
[2025-04-05T17:54:55.749+0000] {taskinstance.py:2614} INFO - Dependencies all met for dep_context=requeueable deps ti=<TaskInstance: fetch_and_store_data.retriving_data_from_postgres manual__2025-04-05T17:20:14.529744+00:00 [queued]>
[2025-04-05T17:54:55.750+0000] {taskinstance.py:2867} INFO - Starting attempt 1 of 2
[2025-04-05T17:54:55.810+0000] {taskinstance.py:2890} INFO - Executing <Task(PythonOperator): retriving_data_from_postgres> on 2025-04-05 17:20:14.529744+00:00
[2025-04-05T17:54:55.818+0000] {standard_task_runner.py:72} INFO - Started process 394 to run task
[2025-04-05T17:54:55.822+0000] {standard_task_runner.py:104} INFO - Running: ['airflow', 'tasks', 'run', 'fetch_and_store_data', 'retriving_data_from_postgres', 'manual__2025-04-05T17:20:14.529744+00:00', '--job-id', '18', '--raw', '--subdir', 'DAGS_FOLDER/reverse_etl_dag.py', '--cfg-path', '/tmp/tmp3gyd6rwz']
[2025-04-05T17:54:55.826+0000] {standard_task_runner.py:105} INFO - Job 18: Subtask retriving_data_from_postgres
[2025-04-05T17:54:55.949+0000] {task_command.py:467} INFO - Running <TaskInstance: fetch_and_store_data.retriving_data_from_postgres manual__2025-04-05T17:20:14.529744+00:00 [running]> on host 20f80019eeb6
[2025-04-05T17:54:56.159+0000] {taskinstance.py:3134} INFO - Exporting env vars: AIRFLOW_CTX_DAG_OWNER='airflow' AIRFLOW_CTX_DAG_ID='fetch_and_store_data' AIRFLOW_CTX_TASK_ID='retriving_data_from_postgres' AIRFLOW_CTX_EXECUTION_DATE='2025-04-05T17:20:14.529744+00:00' AIRFLOW_CTX_TRY_NUMBER='1' AIRFLOW_CTX_DAG_RUN_ID='manual__2025-04-05T17:20:14.529744+00:00'
[2025-04-05T17:54:56.160+0000] {taskinstance.py:732} INFO - ::endgroup::
[2025-04-05T17:54:58.050+0000] {logging_mixin.py:190} INFO - Access token retrieved: eyJhbGciOiJSUzI1NiIsInR5cCIgOiAiSldUIiwia2lkIiA6ICJ6Z1BPdmhDSC1Ic21OQnhhV3lnLU11dlF6dHJERTBDSEJHZDB2MVh0Vnk0In0.eyJleHAiOjE3NDM4NzY1OTcsImlhdCI6MTc0Mzg3NTY5NywianRpIjoiNWFlNjhiMzktYTY4Mi00YzM2LWJjMmYtYjllN2RmMDc2OTdmIiwiaXNzIjoiaHR0cHM6Ly9jbG91ZC5haXJieXRlLmNvbS9hdXRoL3JlYWxtcy9fYWlyYnl0ZS1hcHBsaWNhdGlvbi1jbGllbnRzIiwiYXVkIjoiYWNjb3VudCIsInN1YiI6IjIzMzZjOWQyLTQ4OTUtNGY5NS04NDJiLTRjZjE2NTg1YmUxMyIsInR5cCI6IkJlYXJlciIsImF6cCI6IjE0MWZkYTI2LTViODctNDZjYi1iODZlLTdhYTQxNjZiYWJhZCIsImFjciI6IjEiLCJyZWFsbV9hY2Nlc3MiOnsicm9sZXMiOlsib2ZmbGluZV9hY2Nlc3MiLCJ1bWFfYXV0aG9yaXphdGlvbiIsImRlZmF1bHQtcm9sZXMtX2FpcmJ5dGUtYXBwbGljYXRpb24tY2xpZW50cyJdfSwicmVzb3VyY2VfYWNjZXNzIjp7ImFjY291bnQiOnsicm9sZXMiOlsibWFuYWdlLWFjY291bnQiLCJtYW5hZ2UtYWNjb3VudC1saW5rcyIsInZpZXctcHJvZmlsZSJdfX0sInNjb3BlIjoib3BlbmlkIGVtYWlsIHByb2ZpbGUiLCJlbWFpbF92ZXJpZmllZCI6ZmFsc2UsImNsaWVudEhvc3QiOiIxNzIuMjMuMC45IiwidXNlcl9pZCI6IjIzMzZjOWQyLTQ4OTUtNGY5NS04NDJiLTRjZjE2NTg1YmUxMyIsInByZWZlcnJlZF91c2VybmFtZSI6InNlcnZpY2UtYWNjb3VudC0xNDFmZGEyNi01Yjg3LTQ2Y2ItYjg2ZS03YWE0MTY2YmFiYWQiLCJjbGllbnRBZGRyZXNzIjoiMTcyLjIzLjAuOSIsImNsaWVudF9pZCI6IjE0MWZkYTI2LTViODctNDZjYi1iODZlLTdhYTQxNjZiYWJhZCJ9.a0w-UW2Dq4aMLjEXF67LKo-9MEWj1JwIPr9s4UyAHcFe-lwCC1Q3yrALmXN_sWazRj5cIyB-dtpaaFTZXg-txzVwNQf40ZTK5D3IwH63dRcASsvaGCV993Kw8uctonoogcZ3DQd4m5-f2VuiRMPtxcMu3jyf2vYjRz2_02ZditVw5teeZ3qn9HEdOmRAJMpcLMmOZnwaNYD_n8b5tI9PgI7Pt-kSbCkjrSk04UtgFDP3Wmg7tGycPuxlW0cdylyvQ2Ihvj7yfkEkiRiN1858uco-6h8jDufBjtca7vwza_tlVanq5ricUhLo98j9pZV7S1AwJfzNqfcYAzk7vjMnkA
[2025-04-05T17:54:58.845+0000] {taskinstance.py:3313} ERROR - Task failed with exception
Traceback (most recent call last):
  File "/home/airflow/.local/lib/python3.12/site-packages/airflow/models/taskinstance.py", line 768, in _execute_task
    result = _execute_callable(context=context, **execute_callable_kwargs)
             ^^^^^^^^^^^^^^^^^^^^^^^^^^^^^^^^^^^^^^^^^^^^^^^^^^^^^^^^^^^^^
  File "/home/airflow/.local/lib/python3.12/site-packages/airflow/models/taskinstance.py", line 734, in _execute_callable
    return ExecutionCallableRunner(
           ^^^^^^^^^^^^^^^^^^^^^^^^
  File "/home/airflow/.local/lib/python3.12/site-packages/airflow/utils/operator_helpers.py", line 252, in run
    return self.func(*args, **kwargs)
           ^^^^^^^^^^^^^^^^^^^^^^^^^^
  File "/home/airflow/.local/lib/python3.12/site-packages/airflow/models/baseoperator.py", line 424, in wrapper
    return func(self, *args, **kwargs)
           ^^^^^^^^^^^^^^^^^^^^^^^^^^^
  File "/home/airflow/.local/lib/python3.12/site-packages/airflow/operators/python.py", line 238, in execute
    return_value = self.execute_callable()
                   ^^^^^^^^^^^^^^^^^^^^^^^
  File "/home/airflow/.local/lib/python3.12/site-packages/airflow/operators/python.py", line 256, in execute_callable
    return runner.run(*self.op_args, **self.op_kwargs)
           ^^^^^^^^^^^^^^^^^^^^^^^^^^^^^^^^^^^^^^^^^^^
  File "/home/airflow/.local/lib/python3.12/site-packages/airflow/utils/operator_helpers.py", line 252, in run
    return self.func(*args, **kwargs)
           ^^^^^^^^^^^^^^^^^^^^^^^^^^
  File "/usr/local/airflow/dags/reverse_etl_dag.py", line 62, in trigger_airbyte_sync
    raise AirflowException(
airflow.exceptions.AirflowException: Failed to trigger Airbyte connection. Response: {"status":409,"type":"https://reference.airbyte.com/reference/errors#try-again-later","title":"try-again-later","detail":"Please try again later.","documentationUrl":null,"data":{"message":"A sync is already running for: d22193d6-ce77-4ca2-b336-03826b5174c3"}}
[2025-04-05T17:54:58.866+0000] {taskinstance.py:1226} INFO - Marking task as UP_FOR_RETRY. dag_id=fetch_and_store_data, task_id=retriving_data_from_postgres, run_id=manual__2025-04-05T17:20:14.529744+00:00, execution_date=20250405T172014, start_date=20250405T175455, end_date=20250405T175458
[2025-04-05T17:54:59.004+0000] {taskinstance.py:341} INFO - ::group::Post task execution logs
[2025-04-05T17:54:59.006+0000] {standard_task_runner.py:124} ERROR - Failed to execute job 18 for task retriving_data_from_postgres (Failed to trigger Airbyte connection. Response: {"status":409,"type":"https://reference.airbyte.com/reference/errors#try-again-later","title":"try-again-later","detail":"Please try again later.","documentationUrl":null,"data":{"message":"A sync is already running for: d22193d6-ce77-4ca2-b336-03826b5174c3"}}; 394)
Traceback (most recent call last):
  File "/home/airflow/.local/lib/python3.12/site-packages/airflow/task/task_runner/standard_task_runner.py", line 117, in _start_by_fork
    ret = args.func(args, dag=self.dag)
          ^^^^^^^^^^^^^^^^^^^^^^^^^^^^^
  File "/home/airflow/.local/lib/python3.12/site-packages/airflow/cli/cli_config.py", line 49, in command
    return func(*args, **kwargs)
           ^^^^^^^^^^^^^^^^^^^^^
  File "/home/airflow/.local/lib/python3.12/site-packages/airflow/utils/cli.py", line 116, in wrapper
    return f(*args, **kwargs)
           ^^^^^^^^^^^^^^^^^^
  File "/home/airflow/.local/lib/python3.12/site-packages/airflow/cli/commands/task_command.py", line 483, in task_run
    task_return_code = _run_task_by_selected_method(args, _dag, ti)
                       ^^^^^^^^^^^^^^^^^^^^^^^^^^^^^^^^^^^^^^^^^^^^
  File "/home/airflow/.local/lib/python3.12/site-packages/airflow/cli/commands/task_command.py", line 256, in _run_task_by_selected_method
    return _run_raw_task(args, ti)
           ^^^^^^^^^^^^^^^^^^^^^^^
  File "/home/airflow/.local/lib/python3.12/site-packages/airflow/cli/commands/task_command.py", line 341, in _run_raw_task
    return ti._run_raw_task(
           ^^^^^^^^^^^^^^^^^
  File "/home/airflow/.local/lib/python3.12/site-packages/airflow/utils/session.py", line 97, in wrapper
    return func(*args, session=session, **kwargs)
           ^^^^^^^^^^^^^^^^^^^^^^^^^^^^^^^^^^^^^^
  File "/home/airflow/.local/lib/python3.12/site-packages/airflow/models/taskinstance.py", line 3006, in _run_raw_task
    return _run_raw_task(
           ^^^^^^^^^^^^^^
  File "/home/airflow/.local/lib/python3.12/site-packages/airflow/models/taskinstance.py", line 274, in _run_raw_task
    TaskInstance._execute_task_with_callbacks(
  File "/home/airflow/.local/lib/python3.12/site-packages/airflow/models/taskinstance.py", line 3161, in _execute_task_with_callbacks
    result = self._execute_task(context, task_orig)
             ^^^^^^^^^^^^^^^^^^^^^^^^^^^^^^^^^^^^^^
  File "/home/airflow/.local/lib/python3.12/site-packages/airflow/models/taskinstance.py", line 3185, in _execute_task
    return _execute_task(self, context, task_orig)
           ^^^^^^^^^^^^^^^^^^^^^^^^^^^^^^^^^^^^^^^
  File "/home/airflow/.local/lib/python3.12/site-packages/airflow/models/taskinstance.py", line 768, in _execute_task
    result = _execute_callable(context=context, **execute_callable_kwargs)
             ^^^^^^^^^^^^^^^^^^^^^^^^^^^^^^^^^^^^^^^^^^^^^^^^^^^^^^^^^^^^^
  File "/home/airflow/.local/lib/python3.12/site-packages/airflow/models/taskinstance.py", line 734, in _execute_callable
    return ExecutionCallableRunner(
           ^^^^^^^^^^^^^^^^^^^^^^^^
  File "/home/airflow/.local/lib/python3.12/site-packages/airflow/utils/operator_helpers.py", line 252, in run
    return self.func(*args, **kwargs)
           ^^^^^^^^^^^^^^^^^^^^^^^^^^
  File "/home/airflow/.local/lib/python3.12/site-packages/airflow/models/baseoperator.py", line 424, in wrapper
    return func(self, *args, **kwargs)
           ^^^^^^^^^^^^^^^^^^^^^^^^^^^
  File "/home/airflow/.local/lib/python3.12/site-packages/airflow/operators/python.py", line 238, in execute
    return_value = self.execute_callable()
                   ^^^^^^^^^^^^^^^^^^^^^^^
  File "/home/airflow/.local/lib/python3.12/site-packages/airflow/operators/python.py", line 256, in execute_callable
    return runner.run(*self.op_args, **self.op_kwargs)
           ^^^^^^^^^^^^^^^^^^^^^^^^^^^^^^^^^^^^^^^^^^^
  File "/home/airflow/.local/lib/python3.12/site-packages/airflow/utils/operator_helpers.py", line 252, in run
    return self.func(*args, **kwargs)
           ^^^^^^^^^^^^^^^^^^^^^^^^^^
  File "/usr/local/airflow/dags/reverse_etl_dag.py", line 62, in trigger_airbyte_sync
    raise AirflowException(
airflow.exceptions.AirflowException: Failed to trigger Airbyte connection. Response: {"status":409,"type":"https://reference.airbyte.com/reference/errors#try-again-later","title":"try-again-later","detail":"Please try again later.","documentationUrl":null,"data":{"message":"A sync is already running for: d22193d6-ce77-4ca2-b336-03826b5174c3"}}
[2025-04-05T17:54:59.050+0000] {local_task_job_runner.py:266} INFO - Task exited with return code 1
[2025-04-05T17:54:59.098+0000] {taskinstance.py:3901} INFO - 0 downstream tasks scheduled from follow-on schedule check
[2025-04-05T17:54:59.101+0000] {local_task_job_runner.py:245} INFO - ::endgroup::
